{
 "cells": [
  {
   "cell_type": "code",
   "execution_count": 2,
   "id": "61e4ae02-1e0e-43e4-8a75-bc1714c91696",
   "metadata": {},
   "outputs": [
    {
     "ename": "ModuleNotFoundError",
     "evalue": "No module named 'face_recognition'",
     "output_type": "error",
     "traceback": [
      "\u001b[1;31m---------------------------------------------------------------------------\u001b[0m",
      "\u001b[1;31mModuleNotFoundError\u001b[0m                       Traceback (most recent call last)",
      "Cell \u001b[1;32mIn [2], line 1\u001b[0m\n\u001b[1;32m----> 1\u001b[0m \u001b[38;5;28;01mimport\u001b[39;00m \u001b[38;5;21;01mface_recognition\u001b[39;00m\n\u001b[0;32m      2\u001b[0m image \u001b[38;5;241m=\u001b[39m face_recognition\u001b[38;5;241m.\u001b[39mload_image_file(\u001b[38;5;124m\"\u001b[39m\u001b[38;5;124mtest.jpg\u001b[39m\u001b[38;5;124m\"\u001b[39m)\n\u001b[0;32m      3\u001b[0m face_locations \u001b[38;5;241m=\u001b[39m face_recognition\u001b[38;5;241m.\u001b[39mface_locations(image)\n",
      "\u001b[1;31mModuleNotFoundError\u001b[0m: No module named 'face_recognition'"
     ]
    }
   ],
   "source": [
    "import face_recognition\n",
    "image = face_recognition.load_image_file(\"test.jpg\")\n",
    "face_locations = face_recognition.face_locations(image)"
   ]
  },
  {
   "cell_type": "code",
   "execution_count": 3,
   "id": "7c0ac83f-19f5-4b35-af36-362290812217",
   "metadata": {},
   "outputs": [
    {
     "name": "stdout",
     "output_type": "stream",
     "text": [
      "Collecting face_recognition\n",
      "  Using cached face_recognition-1.3.0-py2.py3-none-any.whl (15 kB)\n",
      "Requirement already satisfied: numpy in d:\\myapps\\anaconda3\\envs\\iot\\lib\\site-packages (from face_recognition) (1.23.5)\n",
      "Requirement already satisfied: face-recognition-models>=0.3.0 in d:\\myapps\\anaconda3\\envs\\iot\\lib\\site-packages (from face_recognition) (0.3.0)\n",
      "Requirement already satisfied: Pillow in d:\\myapps\\anaconda3\\envs\\iot\\lib\\site-packages (from face_recognition) (9.3.0)\n",
      "Collecting dlib>=19.7\n",
      "  Using cached dlib-19.24.0.tar.gz (3.2 MB)\n",
      "  Preparing metadata (setup.py): started\n",
      "  Preparing metadata (setup.py): finished with status 'done'\n",
      "Collecting Click>=6.0\n",
      "  Using cached click-8.1.3-py3-none-any.whl (96 kB)\n",
      "Requirement already satisfied: colorama in d:\\myapps\\anaconda3\\envs\\iot\\lib\\site-packages (from Click>=6.0->face_recognition) (0.4.5)\n",
      "Building wheels for collected packages: dlib\n",
      "  Building wheel for dlib (setup.py): started\n",
      "  Building wheel for dlib (setup.py): finished with status 'error'\n",
      "  Running setup.py clean for dlib\n",
      "Failed to build dlib\n",
      "Installing collected packages: dlib, Click, face_recognition\n",
      "  Running setup.py install for dlib: started\n",
      "  Running setup.py install for dlib: finished with status 'error'\n"
     ]
    },
    {
     "name": "stderr",
     "output_type": "stream",
     "text": [
      "  error: subprocess-exited-with-error\n",
      "  \n",
      "  python setup.py bdist_wheel did not run successfully.\n",
      "  exit code: 1\n",
      "  \n",
      "  [65 lines of output]\n",
      "  running bdist_wheel\n",
      "  running build\n",
      "  running build_py\n",
      "  running build_ext\n",
      "  C:\\Users\\pc\\AppData\\Local\\Temp\\pip-install-er0wgmiv\\dlib_c1721912d9d946a0a1a784eb351521c0\\setup.py:129: DeprecationWarning: distutils Version classes are deprecated. Use packaging.version instead.\n",
      "    if LooseVersion(cmake_version) < '3.1.0':\n",
      "  Building extension for Python 3.9.15 (main, Nov 24 2022, 14:39:17) [MSC v.1916 64 bit (AMD64)]\n",
      "  Invoking CMake setup: 'cmake C:\\Users\\pc\\AppData\\Local\\Temp\\pip-install-er0wgmiv\\dlib_c1721912d9d946a0a1a784eb351521c0\\tools\\python -DCMAKE_LIBRARY_OUTPUT_DIRECTORY=C:\\Users\\pc\\AppData\\Local\\Temp\\pip-install-er0wgmiv\\dlib_c1721912d9d946a0a1a784eb351521c0\\build\\lib.win-amd64-cpython-39 -DPYTHON_EXECUTABLE=D:\\myApps\\anaconda3\\envs\\IOT\\python.exe -DCMAKE_LIBRARY_OUTPUT_DIRECTORY_RELEASE=C:\\Users\\pc\\AppData\\Local\\Temp\\pip-install-er0wgmiv\\dlib_c1721912d9d946a0a1a784eb351521c0\\build\\lib.win-amd64-cpython-39 -A x64'\n",
      "  -- Building for: Visual Studio 17 2022\n",
      "  -- Selecting Windows SDK version 10.0.19041.0 to target Windows 10.0.19044.\n",
      "  -- The C compiler identification is unknown\n",
      "  -- The CXX compiler identification is unknown\n",
      "  CMake Error at CMakeLists.txt:14 (project):\n",
      "    No CMAKE_C_COMPILER could be found.\n",
      "  \n",
      "  \n",
      "  \n",
      "  CMake Error at CMakeLists.txt:14 (project):\n",
      "    No CMAKE_CXX_COMPILER could be found.\n",
      "  \n",
      "  \n",
      "  \n",
      "  -- Configuring incomplete, errors occurred!\n",
      "  See also \"C:/Users/pc/AppData/Local/Temp/pip-install-er0wgmiv/dlib_c1721912d9d946a0a1a784eb351521c0/build/temp.win-amd64-cpython-39/Release/CMakeFiles/CMakeOutput.log\".\n",
      "  See also \"C:/Users/pc/AppData/Local/Temp/pip-install-er0wgmiv/dlib_c1721912d9d946a0a1a784eb351521c0/build/temp.win-amd64-cpython-39/Release/CMakeFiles/CMakeError.log\".\n",
      "  Traceback (most recent call last):\n",
      "    File \"<string>\", line 2, in <module>\n",
      "    File \"<pip-setuptools-caller>\", line 34, in <module>\n",
      "    File \"C:\\Users\\pc\\AppData\\Local\\Temp\\pip-install-er0wgmiv\\dlib_c1721912d9d946a0a1a784eb351521c0\\setup.py\", line 222, in <module>\n",
      "      setup(\n",
      "    File \"D:\\myApps\\anaconda3\\envs\\IOT\\lib\\site-packages\\setuptools\\__init__.py\", line 87, in setup\n",
      "      return distutils.core.setup(**attrs)\n",
      "    File \"D:\\myApps\\anaconda3\\envs\\IOT\\lib\\site-packages\\setuptools\\_distutils\\core.py\", line 185, in setup\n",
      "      return run_commands(dist)\n",
      "    File \"D:\\myApps\\anaconda3\\envs\\IOT\\lib\\site-packages\\setuptools\\_distutils\\core.py\", line 201, in run_commands\n",
      "      dist.run_commands()\n",
      "    File \"D:\\myApps\\anaconda3\\envs\\IOT\\lib\\site-packages\\setuptools\\_distutils\\dist.py\", line 968, in run_commands\n",
      "      self.run_command(cmd)\n",
      "    File \"D:\\myApps\\anaconda3\\envs\\IOT\\lib\\site-packages\\setuptools\\dist.py\", line 1217, in run_command\n",
      "      super().run_command(command)\n",
      "    File \"D:\\myApps\\anaconda3\\envs\\IOT\\lib\\site-packages\\setuptools\\_distutils\\dist.py\", line 987, in run_command\n",
      "      cmd_obj.run()\n",
      "    File \"D:\\myApps\\anaconda3\\envs\\IOT\\lib\\site-packages\\wheel\\bdist_wheel.py\", line 299, in run\n",
      "      self.run_command('build')\n",
      "    File \"D:\\myApps\\anaconda3\\envs\\IOT\\lib\\site-packages\\setuptools\\_distutils\\cmd.py\", line 319, in run_command\n",
      "      self.distribution.run_command(command)\n",
      "    File \"D:\\myApps\\anaconda3\\envs\\IOT\\lib\\site-packages\\setuptools\\dist.py\", line 1217, in run_command\n",
      "      super().run_command(command)\n",
      "    File \"D:\\myApps\\anaconda3\\envs\\IOT\\lib\\site-packages\\setuptools\\_distutils\\dist.py\", line 987, in run_command\n",
      "      cmd_obj.run()\n",
      "    File \"D:\\myApps\\anaconda3\\envs\\IOT\\lib\\site-packages\\setuptools\\_distutils\\command\\build.py\", line 132, in run\n",
      "      self.run_command(cmd_name)\n",
      "    File \"D:\\myApps\\anaconda3\\envs\\IOT\\lib\\site-packages\\setuptools\\_distutils\\cmd.py\", line 319, in run_command\n",
      "      self.distribution.run_command(command)\n",
      "    File \"D:\\myApps\\anaconda3\\envs\\IOT\\lib\\site-packages\\setuptools\\dist.py\", line 1217, in run_command\n",
      "      super().run_command(command)\n",
      "    File \"D:\\myApps\\anaconda3\\envs\\IOT\\lib\\site-packages\\setuptools\\_distutils\\dist.py\", line 987, in run_command\n",
      "      cmd_obj.run()\n",
      "    File \"C:\\Users\\pc\\AppData\\Local\\Temp\\pip-install-er0wgmiv\\dlib_c1721912d9d946a0a1a784eb351521c0\\setup.py\", line 134, in run\n",
      "      self.build_extension(ext)\n",
      "    File \"C:\\Users\\pc\\AppData\\Local\\Temp\\pip-install-er0wgmiv\\dlib_c1721912d9d946a0a1a784eb351521c0\\setup.py\", line 171, in build_extension\n",
      "      subprocess.check_call(cmake_setup, cwd=build_folder)\n",
      "    File \"D:\\myApps\\anaconda3\\envs\\IOT\\lib\\subprocess.py\", line 373, in check_call\n",
      "      raise CalledProcessError(retcode, cmd)\n",
      "  subprocess.CalledProcessError: Command '['cmake', 'C:\\\\Users\\\\pc\\\\AppData\\\\Local\\\\Temp\\\\pip-install-er0wgmiv\\\\dlib_c1721912d9d946a0a1a784eb351521c0\\\\tools\\\\python', '-DCMAKE_LIBRARY_OUTPUT_DIRECTORY=C:\\\\Users\\\\pc\\\\AppData\\\\Local\\\\Temp\\\\pip-install-er0wgmiv\\\\dlib_c1721912d9d946a0a1a784eb351521c0\\\\build\\\\lib.win-amd64-cpython-39', '-DPYTHON_EXECUTABLE=D:\\\\myApps\\\\anaconda3\\\\envs\\\\IOT\\\\python.exe', '-DCMAKE_LIBRARY_OUTPUT_DIRECTORY_RELEASE=C:\\\\Users\\\\pc\\\\AppData\\\\Local\\\\Temp\\\\pip-install-er0wgmiv\\\\dlib_c1721912d9d946a0a1a784eb351521c0\\\\build\\\\lib.win-amd64-cpython-39', '-A', 'x64']' returned non-zero exit status 1.\n",
      "  [end of output]\n",
      "  \n",
      "  note: This error originates from a subprocess, and is likely not a problem with pip.\n",
      "  ERROR: Failed building wheel for dlib\n",
      "  error: subprocess-exited-with-error\n",
      "  \n",
      "  Running setup.py install for dlib did not run successfully.\n",
      "  exit code: 1\n",
      "  \n",
      "  [69 lines of output]\n",
      "  running install\n",
      "  D:\\myApps\\anaconda3\\envs\\IOT\\lib\\site-packages\\setuptools\\command\\install.py:34: SetuptoolsDeprecationWarning: setup.py install is deprecated. Use build and pip and other standards-based tools.\n",
      "    warnings.warn(\n",
      "  running build\n",
      "  running build_py\n",
      "  running build_ext\n",
      "  C:\\Users\\pc\\AppData\\Local\\Temp\\pip-install-er0wgmiv\\dlib_c1721912d9d946a0a1a784eb351521c0\\setup.py:129: DeprecationWarning: distutils Version classes are deprecated. Use packaging.version instead.\n",
      "    if LooseVersion(cmake_version) < '3.1.0':\n",
      "  Building extension for Python 3.9.15 (main, Nov 24 2022, 14:39:17) [MSC v.1916 64 bit (AMD64)]\n",
      "  Invoking CMake setup: 'cmake C:\\Users\\pc\\AppData\\Local\\Temp\\pip-install-er0wgmiv\\dlib_c1721912d9d946a0a1a784eb351521c0\\tools\\python -DCMAKE_LIBRARY_OUTPUT_DIRECTORY=C:\\Users\\pc\\AppData\\Local\\Temp\\pip-install-er0wgmiv\\dlib_c1721912d9d946a0a1a784eb351521c0\\build\\lib.win-amd64-cpython-39 -DPYTHON_EXECUTABLE=D:\\myApps\\anaconda3\\envs\\IOT\\python.exe -DCMAKE_LIBRARY_OUTPUT_DIRECTORY_RELEASE=C:\\Users\\pc\\AppData\\Local\\Temp\\pip-install-er0wgmiv\\dlib_c1721912d9d946a0a1a784eb351521c0\\build\\lib.win-amd64-cpython-39 -A x64'\n",
      "  -- Building for: Visual Studio 17 2022\n",
      "  -- Selecting Windows SDK version 10.0.19041.0 to target Windows 10.0.19044.\n",
      "  -- The C compiler identification is unknown\n",
      "  -- The CXX compiler identification is unknown\n",
      "  CMake Error at CMakeLists.txt:14 (project):\n",
      "    No CMAKE_C_COMPILER could be found.\n",
      "  \n",
      "  \n",
      "  \n",
      "  CMake Error at CMakeLists.txt:14 (project):\n",
      "    No CMAKE_CXX_COMPILER could be found.\n",
      "  \n",
      "  \n",
      "  \n",
      "  -- Configuring incomplete, errors occurred!\n",
      "  See also \"C:/Users/pc/AppData/Local/Temp/pip-install-er0wgmiv/dlib_c1721912d9d946a0a1a784eb351521c0/build/temp.win-amd64-cpython-39/Release/CMakeFiles/CMakeOutput.log\".\n",
      "  See also \"C:/Users/pc/AppData/Local/Temp/pip-install-er0wgmiv/dlib_c1721912d9d946a0a1a784eb351521c0/build/temp.win-amd64-cpython-39/Release/CMakeFiles/CMakeError.log\".\n",
      "  Traceback (most recent call last):\n",
      "    File \"<string>\", line 2, in <module>\n",
      "    File \"<pip-setuptools-caller>\", line 34, in <module>\n",
      "    File \"C:\\Users\\pc\\AppData\\Local\\Temp\\pip-install-er0wgmiv\\dlib_c1721912d9d946a0a1a784eb351521c0\\setup.py\", line 222, in <module>\n",
      "      setup(\n",
      "    File \"D:\\myApps\\anaconda3\\envs\\IOT\\lib\\site-packages\\setuptools\\__init__.py\", line 87, in setup\n",
      "      return distutils.core.setup(**attrs)\n",
      "    File \"D:\\myApps\\anaconda3\\envs\\IOT\\lib\\site-packages\\setuptools\\_distutils\\core.py\", line 185, in setup\n",
      "      return run_commands(dist)\n",
      "    File \"D:\\myApps\\anaconda3\\envs\\IOT\\lib\\site-packages\\setuptools\\_distutils\\core.py\", line 201, in run_commands\n",
      "      dist.run_commands()\n",
      "    File \"D:\\myApps\\anaconda3\\envs\\IOT\\lib\\site-packages\\setuptools\\_distutils\\dist.py\", line 968, in run_commands\n",
      "      self.run_command(cmd)\n",
      "    File \"D:\\myApps\\anaconda3\\envs\\IOT\\lib\\site-packages\\setuptools\\dist.py\", line 1217, in run_command\n",
      "      super().run_command(command)\n",
      "    File \"D:\\myApps\\anaconda3\\envs\\IOT\\lib\\site-packages\\setuptools\\_distutils\\dist.py\", line 987, in run_command\n",
      "      cmd_obj.run()\n",
      "    File \"D:\\myApps\\anaconda3\\envs\\IOT\\lib\\site-packages\\setuptools\\command\\install.py\", line 68, in run\n",
      "      return orig.install.run(self)\n",
      "    File \"D:\\myApps\\anaconda3\\envs\\IOT\\lib\\site-packages\\setuptools\\_distutils\\command\\install.py\", line 698, in run\n",
      "      self.run_command('build')\n",
      "    File \"D:\\myApps\\anaconda3\\envs\\IOT\\lib\\site-packages\\setuptools\\_distutils\\cmd.py\", line 319, in run_command\n",
      "      self.distribution.run_command(command)\n",
      "    File \"D:\\myApps\\anaconda3\\envs\\IOT\\lib\\site-packages\\setuptools\\dist.py\", line 1217, in run_command\n",
      "      super().run_command(command)\n",
      "    File \"D:\\myApps\\anaconda3\\envs\\IOT\\lib\\site-packages\\setuptools\\_distutils\\dist.py\", line 987, in run_command\n",
      "      cmd_obj.run()\n",
      "    File \"D:\\myApps\\anaconda3\\envs\\IOT\\lib\\site-packages\\setuptools\\_distutils\\command\\build.py\", line 132, in run\n",
      "      self.run_command(cmd_name)\n",
      "    File \"D:\\myApps\\anaconda3\\envs\\IOT\\lib\\site-packages\\setuptools\\_distutils\\cmd.py\", line 319, in run_command\n",
      "      self.distribution.run_command(command)\n",
      "    File \"D:\\myApps\\anaconda3\\envs\\IOT\\lib\\site-packages\\setuptools\\dist.py\", line 1217, in run_command\n",
      "      super().run_command(command)\n",
      "    File \"D:\\myApps\\anaconda3\\envs\\IOT\\lib\\site-packages\\setuptools\\_distutils\\dist.py\", line 987, in run_command\n",
      "      cmd_obj.run()\n",
      "    File \"C:\\Users\\pc\\AppData\\Local\\Temp\\pip-install-er0wgmiv\\dlib_c1721912d9d946a0a1a784eb351521c0\\setup.py\", line 134, in run\n",
      "      self.build_extension(ext)\n",
      "    File \"C:\\Users\\pc\\AppData\\Local\\Temp\\pip-install-er0wgmiv\\dlib_c1721912d9d946a0a1a784eb351521c0\\setup.py\", line 171, in build_extension\n",
      "      subprocess.check_call(cmake_setup, cwd=build_folder)\n",
      "    File \"D:\\myApps\\anaconda3\\envs\\IOT\\lib\\subprocess.py\", line 373, in check_call\n",
      "      raise CalledProcessError(retcode, cmd)\n",
      "  subprocess.CalledProcessError: Command '['cmake', 'C:\\\\Users\\\\pc\\\\AppData\\\\Local\\\\Temp\\\\pip-install-er0wgmiv\\\\dlib_c1721912d9d946a0a1a784eb351521c0\\\\tools\\\\python', '-DCMAKE_LIBRARY_OUTPUT_DIRECTORY=C:\\\\Users\\\\pc\\\\AppData\\\\Local\\\\Temp\\\\pip-install-er0wgmiv\\\\dlib_c1721912d9d946a0a1a784eb351521c0\\\\build\\\\lib.win-amd64-cpython-39', '-DPYTHON_EXECUTABLE=D:\\\\myApps\\\\anaconda3\\\\envs\\\\IOT\\\\python.exe', '-DCMAKE_LIBRARY_OUTPUT_DIRECTORY_RELEASE=C:\\\\Users\\\\pc\\\\AppData\\\\Local\\\\Temp\\\\pip-install-er0wgmiv\\\\dlib_c1721912d9d946a0a1a784eb351521c0\\\\build\\\\lib.win-amd64-cpython-39', '-A', 'x64']' returned non-zero exit status 1.\n",
      "  [end of output]\n",
      "  \n",
      "  note: This error originates from a subprocess, and is likely not a problem with pip.\n",
      "error: legacy-install-failure\n",
      "\n",
      "Encountered error while trying to install package.\n",
      "\n",
      "dlib\n",
      "\n",
      "note: This is an issue with the package mentioned above, not pip.\n",
      "hint: See above for output from the failure.\n"
     ]
    }
   ],
   "source": [
    "!pip install face_recognition"
   ]
  },
  {
   "cell_type": "code",
   "execution_count": null,
   "id": "e481d782-ded6-4636-967c-41171fd2a318",
   "metadata": {},
   "outputs": [],
   "source": []
  }
 ],
 "metadata": {
  "kernelspec": {
   "display_name": "Python 3",
   "language": "python",
   "name": "python3"
  },
  "language_info": {
   "codemirror_mode": {
    "name": "ipython",
    "version": 3
   },
   "file_extension": ".py",
   "mimetype": "text/x-python",
   "name": "python",
   "nbconvert_exporter": "python",
   "pygments_lexer": "ipython3",
   "version": "3.9.4 (tags/v3.9.4:1f2e308, Apr  6 2021, 13:40:21) [MSC v.1928 64 bit (AMD64)]"
  },
  "vscode": {
   "interpreter": {
    "hash": "81794d4967e6c3204c66dcd87b604927b115b27c00565d3d43f05ba2f3a2cb0d"
   }
  }
 },
 "nbformat": 4,
 "nbformat_minor": 5
}
